Workbook

Sheet Альбомы
A1: ID | B1: Название | C1: ID Исполнителя
A2: 1 | B2: For Those About To Rock We Salute You | C2: 1
A3: 2 | B3: Balls to the Wall | C3: 2
A4: 3 | B4: Restless and Wild | C4: 2
A5: 4 | B5: Let There Be Rock | C5: 1
A6: 5 | B6: Big Ones | C6: 3
A7: 6 | B7: Jagged Little Pill | C7: 4
A8: 7 | B8: Facelift | C8: 5
A9: 8 | B9: Warner 25 Anos | C9: 6
A10: 9 | B10: Plays Metallica By Four Cellos | C10: 7
A11: 10 | B11: Audioslave | C11: 8
A12: 11 | B12: Out Of Exile | C12: 8
A13: 12 | B13: BackBeat Soundtrack | C13: 9
... A348: 347 | B348: Koyaanisqatsi (Soundtrack from the Motion Picture) | C348: 275

Sheet Артисты
A1: ID | B1: Имя
A2: 1 | B2: AC/DC
A3: 2 | B3: Accept
A4: 3 | B4: Aerosmith
A5: 4 | B5: Alanis Morissette
A6: 5 | B6: Alice In Chains
A7: 6 | B7: AntГґnio Carlos Jobim
A8: 7 | B8: Apocalyptica
A9: 8 | B9: Audioslave
A10: 9 | B10: BackBeat
A11: 10 | B11: Billy Cobham
A12: 11 | B12: Black Label Society
A13: 12 | B13: Black Sabbath
... A276: 275 | B276: Philip Glass Ensemble

Sheet Треки
A1: ID | B1: Название трека | C1: ID альбома | D1: ID жанра | E1: Длительность | F1: Размер | G1: Стоимость | H1: band ID | I1: band
A2: 1 | B2: For Those About To Rock (We Salute You) | C2: 1 | D2: 1 | E2: 343719 | F2: 11170334 | G2: 101 | H2: =VLOOKUP(C2,Альбомы!$A:$C,3,0) -> 1 | I2: =VLOOKUP(H2,Артисты!$A:$B,2,0) -> AC/DC
A3: 2 | B3: Balls to the Wall | C3: 2 | D3: 1 | E3: 342562 | F3: 5510424 | G3: 161 | H3: =VLOOKUP(C3,Альбомы!$A:$C,3,0) -> 2 | I3: =VLOOKUP(H3,Артисты!$A:$B,2,0) -> Accept
A4: 3 | B4: Fast As a Shark | C4: 3 | D4: 1 | E4: 230619 | F4: 3990994 | G4: 96 | H4: =VLOOKUP(C4,Альбомы!$A:$C,3,0) -> 2 | I4: =VLOOKUP(H4,Артисты!$A:$B,2,0) -> Accept
A5: 4 | B5: Restless and Wild | C5: 3 | D5: 1 | E5: 252051 | F5: 4331779 | G5: 133 | H5: =VLOOKUP(C5,Альбомы!$A:$C,3,0) -> 2 | I5: =VLOOKUP(H5,Артисты!$A:$B,2,0) -> Accept
A6: 5 | B6: Princess of the Dawn | C6: 3 | D6: 1 | E6: 375418 | F6: 6290521 | G6: 172 | H6: =VLOOKUP(C6,Альбомы!$A:$C,3,0) -> 2 | I6: =VLOOKUP(H6,Артисты!$A:$B,2,0) -> Accept
A7: 6 | B7: Put The Finger On You | C7: 1 | D7: 1 | E7: 205662 | F7: 6713451 | G7: 136 | H7: =VLOOKUP(C7,Альбомы!$A:$C,3,0) -> 1 | I7: =VLOOKUP(H7,Артисты!$A:$B,2,0) -> AC/DC
A8: 7 | B8: Let's Get It Up | C8: 1 | D8: 1 | E8: 233926 | F8: 7636561 | G8: 58 | H8: =VLOOKUP(C8,Альбомы!$A:$C,3,0) -> 1 | I8: =VLOOKUP(H8,Артисты!$A:$B,2,0) -> AC/DC
A9: 8 | B9: Inject The Venom | C9: 1 | D9: 1 | E9: 210834 | F9: 6852860 | G9: 169 | H9: =VLOOKUP(C9,Альбомы!$A:$C,3,0) -> 1 | I9: =VLOOKUP(H9,Артисты!$A:$B,2,0) -> AC/DC
A10: 9 | B10: Snowballed | C10: 1 | D10: 1 | E10: 203102 | F10: 6599424 | G10: 89 | H10: =VLOOKUP(C10,Альбомы!$A:$C,3,0) -> 1 | I10: =VLOOKUP(H10,Артисты!$A:$B,2,0) -> AC/DC
A11: 10 | B11: Evil Walks | C11: 1 | D11: 1 | E11: 263497 | F11: 8611245 | G11: 122 | H11: =VLOOKUP(C11,Альбомы!$A:$C,3,0) -> 1 | I11: =VLOOKUP(H11,Артисты!$A:$B,2,0) -> AC/DC
A12: 11 | B12: C.O.D. | C12: 1 | D12: 1 | E12: 199836 | F12: 6566314 | G12: 160 | H12: =VLOOKUP(C12,Альбомы!$A:$C,3,0) -> 1 | I12: =VLOOKUP(H12,Артисты!$A:$B,2,0) -> AC/DC
A13: 12 | B13: Breaking The Rules | C13: 1 | D13: 1 | E13: 263288 | F13: 8596840 | G13: 161 | H13: =VLOOKUP(C13,Альбомы!$A:$C,3,0) -> 1 | I13: =VLOOKUP(H13,Артисты!$A:$B,2,0) -> AC/DC
... A2496: 2495 | B2496: Bullet With Butterfly Wings | C2496: 202 | D2496: 4 | E2496: 257306 | F2496: 8431747 | G2496: 87 | H2496: =VLOOKUP(C2496,Альбомы!$A:$C,3,0) -> 131 | I2496: =VLOOKUP(H2496,Артисты!$A:$B,2,0) -> Smashing Pumpkins
A2497: 2496 | B2497: 1979 | C2497: 202 | D2497: 4 | E2497: 263653 | F2497: 8728470 | G2497: 149 | H2497: =VLOOKUP(C2497,Альбомы!$A:$C,3,0) -> 131 | I2497: =VLOOKUP(H2497,Артисты!$A:$B,2,0) -> Smashing Pumpkins
A2498: 2497 | B2498: Zero | C2498: 202 | D2498: 4 | E2498: 161123 | F2498: 5267176 | G2498: 68 | H2498: =VLOOKUP(C2498,Альбомы!$A:$C,3,0) -> 131 | I2498: =VLOOKUP(H2498,Артисты!$A:$B,2,0) -> Smashing Pumpkins
A2499: 2498 | B2499: Tonight, Tonight | C2499: 202 | D2499: 4 | E2499: 255686 | F2499: 8351543 | G2499: 50 | H2499: =VLOOKUP(C2499,Альбомы!$A:$C,3,0) -> 131 | I2499: =VLOOKUP(H2499,Артисты!$A:$B,2,0) -> Smashing Pumpkins
A2500: 2499 | B2500: Eye | C2500: 202 | D2500: 4 | E2500: 294530 | F2500: 9784201 | G2500: 72 | H2500: =VLOOKUP(C2500,Альбомы!$A:$C,3,0) -> 131 | I2500: =VLOOKUP(H2500,Артисты!$A:$B,2,0) -> Smashing Pumpkins
A2501: 2500 | B2501: Ava Adore | C2501: 202 | D2501: 4 | E2501: 261433 | F2501: 8590412 | G2501: 125 | H2501: =VLOOKUP(C2501,Альбомы!$A:$C,3,0) -> 131 | I2501: =VLOOKUP(H2501,Артисты!$A:$B,2,0) -> Smashing Pumpkins
A2502: 2501 | B2502: Perfect | C2502: 202 | D2502: 4 | E2502: 203023 | F2502: 6734636 | G2502: 87 | H2502: =VLOOKUP(C2502,Альбомы!$A:$C,3,0) -> 131 | I2502: =VLOOKUP(H2502,Артисты!$A:$B,2,0) -> Smashing Pumpkins
A2503: 2502 | B2503: The Everlasting Gaze | C2503: 202 | D2503: 4 | E2503: 242155 | F2503: 7844404 | G2503: 99 | H2503: =VLOOKUP(C2503,Альбомы!$A:$C,3,0) -> 131 | I2503: =VLOOKUP(H2503,Артисты!$A:$B,2,0) -> Smashing Pumpkins
A2504: 2503 | B2504: Stand Inside Your Love | C2504: 202 | D2504: 4 | E2504: 253753 | F2504: 8270113 | G2504: 71 | H2504: =VLOOKUP(C2504,Альбомы!$A:$C,3,0) -> 131 | I2504: =VLOOKUP(H2504,Артисты!$A:$B,2,0) -> Smashing Pumpkins
A2505: 2504 | B2505: Real Love | C2505: 202 | D2505: 4 | E2505: 250697 | F2505: 8025896 | G2505: 155 | H2505: =VLOOKUP(C2505,Альбомы!$A:$C,3,0) -> 131 | I2505: =VLOOKUP(H2505,Артисты!$A:$B,2,0) -> Smashing Pumpkins
A2506: 2505 | B2506: [Untitled] | C2506: 202 | D2506: 4 | E2506: 231784 | F2506: 7689713 | G2506: 189 | H2506: =VLOOKUP(C2506,Альбомы!$A:$C,3,0) -> 131 | I2506: =VLOOKUP(H2506,Артисты!$A:$B,2,0) -> Smashing Pumpkins
A2507: 2506 | B2507: Nothing To Say | C2507: 203 | D2507: 1 | E2507: 238027 | F2507: 7744833 | G2507: 61 | H2507: =VLOOKUP(C2507,Альбомы!$A:$C,3,0) -> 132 | I2507: =VLOOKUP(H2507,Артисты!$A:$B,2,0) -> Soundgarden
A2508: 2507 | B2508: Flower | C2508: 203 | D2508: 1 | E2508: 208822 | F2508: 6830732 | G2508: 163 | H2508: =VLOOKUP(C2508,Альбомы!$A:$C,3,0) -> 132 | I2508: =VLOOKUP(H2508,Артисты!$A:$B,2,0) -> Soundgarden
A2509: 2508 | B2509: Loud Love | C2509: 203 | D2509: 1 | E2509: 297456 | F2509: 9660953 | G2509: 86 | H2509: =VLOOKUP(C2509,Альбомы!$A:$C,3,0) -> 132 | I2509: =VLOOKUP(H2509,Артисты!$A:$B,2,0) -> Soundgarden
... A2746: 2745 | B2746: Let's See Action | C2746: 221 | D2746: 1 | E2746: 243513 | F2746: 8078418 | G2746: 146 | H2746: =VLOOKUP(C2746,Альбомы!$A:$C,3,0) -> 144 | I2746: =VLOOKUP(H2746,Артисты!$A:$B,2,0) -> The Who
A2747: 2746 | B2747: 42125 | C2747: 221 | D2747: 1 | E2747: 289619 | F2747: 9458549 | G2747: 123 | H2747: =VLOOKUP(C2747,Альбомы!$A:$C,3,0) -> 144 | I2747: =VLOOKUP(H2747,Артисты!$A:$B,2,0) -> The Who
A2748: 2747 | B2748: Join Together | C2748: 221 | D2748: 1 | E2748: 262556 | F2748: 8602485 | G2748: 152 | H2748: =VLOOKUP(C2748,Альбомы!$A:$C,3,0) -> 144 | I2748: =VLOOKUP(H2748,Артисты!$A:$B,2,0) -> The Who
A2749: 2748 | B2749: Squeeze Box | C2749: 221 | D2749: 1 | E2749: 161280 | F2749: 5256508 | G2749: 139 | H2749: =VLOOKUP(C2749,Альбомы!$A:$C,3,0) -> 144 | I2749: =VLOOKUP(H2749,Артисты!$A:$B,2,0) -> The Who
A2750: 2749 | B2750: Who Are You (Single Edit Version) | C2750: 221 | D2750: 1 | E2750: 299232 | F2750: 9900469 | G2750: 196 | H2750: =VLOOKUP(C2750,Альбомы!$A:$C,3,0) -> 144 | I2750: =VLOOKUP(H2750,Артисты!$A:$B,2,0) -> The Who
A2751: 2750 | B2751: You Better You Bet | C2751: 221 | D2751: 1 | E2751: 338520 | F2751: 11160877 | G2751: 75 | H2751: =VLOOKUP(C2751,Альбомы!$A:$C,3,0) -> 144 | I2751: =VLOOKUP(H2751,Артисты!$A:$B,2,0) -> The Who
A2752: 2751 | B2752: Primavera | C2752: 222 | D2752: 7 | E2752: 126615 | F2752: 4152604 | G2752: 189 | H2752: =VLOOKUP(C2752,Альбомы!$A:$C,3,0) -> 145 | I2752: =VLOOKUP(H2752,Артисты!$A:$B,2,0) -> Tim Maia
A2753: 2752 | B2753: Chocolate | C2753: 222 | D2753: 7 | E2753: 194690 | F2753: 6411587 | G2753: 116 | H2753: =VLOOKUP(C2753,Альбомы!$A:$C,3,0) -> 145 | I2753: =VLOOKUP(H2753,Артисты!$A:$B,2,0) -> Tim Maia
A2754: 2753 | B2754: Azul Da Cor Do Mar | C2754: 222 | D2754: 7 | E2754: 197955 | F2754: 6475007 | G2754: 70 | H2754: =VLOOKUP(C2754,Альбомы!$A:$C,3,0) -> 145 | I2754: =VLOOKUP(H2754,Артисты!$A:$B,2,0) -> Tim Maia
A2755: 2754 | B2755: O Descobridor Dos Sete Mares | C2755: 222 | D2755: 7 | E2755: 262974 | F2755: 8749583 | G2755: 113 | H2755: =VLOOKUP(C2755,Альбомы!$A:$C,3,0) -> 145 | I2755: =VLOOKUP(H2755,Артисты!$A:$B,2,0) -> Tim Maia
A2756: 2755 | B2756: AtГ© Que Enfim Encontrei VocГЄ | C2756: 222 | D2756: 7 | E2756: 105064 | F2756: 3477751 | G2756: 167 | H2756: =VLOOKUP(C2756,Альбомы!$A:$C,3,0) -> 145 | I2756: =VLOOKUP(H2756,Артисты!$A:$B,2,0) -> Tim Maia
A2757: 2756 | B2757: CoronГ© Antonio Bento | C2757: 222 | D2757: 7 | E2757: 131317 | F2757: 4340326 | G2757: 106 | H2757: =VLOOKUP(C2757,Альбомы!$A:$C,3,0) -> 145 | I2757: =VLOOKUP(H2757,Артисты!$A:$B,2,0) -> Tim Maia
A2758: 2757 | B2758: New Love | C2758: 222 | D2758: 7 | E2758: 237897 | F2758: 7786824 | G2758: 103 | H2758: =VLOOKUP(C2758,Альбомы!$A:$C,3,0) -> 145 | I2758: =VLOOKUP(H2758,Артисты!$A:$B,2,0) -> Tim Maia
...

Sheet Жанры
A1: ID | B1: Название
A2: 1 | B2: Rock
A3: 2 | B3: Jazz
A4: 3 | B4: Metal
A5: 4 | B5: Alternative & Punk
A6: 5 | B6: Rock And Roll
A7: 6 | B7: Blues
A8: 7 | B8: Latin
A9: 8 | B9: Reggae
A10: 9 | B10: Pop
A11: 10 | B11: Soundtrack
A12: 11 | B12: Bossa Nova
A13: 12 | B13: Easy Listening
... A26: 25 | B26: Opera

Sheet Лист5
A1: 273552 | C1: =SUM(A:A) -> 12355529 | D1: =C1/60000 -> 205.92548 | E1: 205 | G1: https://kompege.ru/task
A2: 202824 | G2: № 2057 (Уровень: Средний)
A3: 268537
A4: 263893
A5: 228924
A6: 406347
A7: 219961
A8: 231640
A9: 356424
A10: 197135
A11: 206400
A12: 375349
A13: 182321
A14: 298374
... A42: 84532
